Workbook

Sheet 月報
B2: MQ指標実績表 | K2: =TEXT(X2,"yyyy年m月度") -> @対象年月 | X2: @対象年月
B4: Ⅰ．概要
C5: 項 目 | D5: 系停止 回数 (保全要因) | E5: 系停止 時間 (保全要因) | F5: 故障1 件数 | G5: 故障2 件数 | H5: 予知 修理 件数 | I5: 作業 総件数 | J5: 計画 作業 件数 | K5: 計画 作業率 | L5: 呼び出し 回数 | R5: 工場 | S5: @工場
R6: プラント | S6: @プラント
C7: 当 月 | D7: =P13 -> @集計項目出力5 | E7: =P19 -> 0 | F7: =P25 -> 0 | G7: =P31 -> 0 | H7: =P33 -> 0 | I7: =P49 -> 0 | J7: =P41 -> 0 | K7: =P51 -> 0 | L7: =P67 -> 0 | R7: 工程 | S7: @工程
C8: 累計（半期） | D8: =V13 -> @集計項目出力10 | E8: =V19 -> 0 | F8: =V25 -> 0 | G8: =V31 -> 0 | H8: =V33 -> 0 | I8: =V49 -> 0 | J8: =V41 -> 0 | K8: =V51 -> 0 | L8: =V67 -> 0 | R8: 職種 | S8: @職種
C9: 累計（年度） | D9: =V14 -> @集計項目出力15 | E9: =V20 -> 0 | F9: =V26 -> 0 | G9: =V32 -> 0 | H9: =V34 -> 0 | I9: =V50 -> 0 | J9: =V42 -> 0 | K9: =V52 -> 0 | L9: =V68 -> 0
B11: Ⅱ．詳細 | L11: 当月 | Q11: 累計
G12: 項 目 | L12: 機 械 | M12: 電 気 | N12: 計 装 | O12: その他 | P12: 合 計 | R12: 機 械 | S12: 電 気 | T12: 計 装 | U12: その他 | V12: 合 計
C13: 系 の 停 止 | D13: ★ 系 停 止 回 数 | G13: ★ 保全要因 | L13: @集計項目出力1 | M13: @集計項目出力2 | N13: @集計項目出力3 | O13: @集計項目出力4 | P13: @集計項目出力5 | Q13: 半期 | R13: @集計項目出力6 | S13: @集計項目出力7 | T13: @集計項目出力8 | U13: @集計項目出力9 | V13: @集計項目出力10
Q14: 年度 | R14: @集計項目出力11 | S14: @集計項目出力12 | T14: @集計項目出力13 | U14: @集計項目出力14 | V14: @集計項目出力15
G15: ★ 製造要因 | Q15: 半期
Q16: 年度
G17: 計 | Q17: 半期
Q18: 年度
D19: ★ 系 停 止 時 間 （保全要因） ［Ｈｒ] | Q19: 半期
Q20: 年度
C21: 故障修理件数 | D21: ★ 故 障 1 | G21: ★ TBM 故障 | Q21: 半期
Q22: 年度
G23: ★ CBM 想定外故障 | Q23: 半期
Q24: 年度
G25: 計 | K25: (a) | Q25: 半期
Q26: 年度
D27: ★ 故 障 2 | G27: ★ CBM 想定内故障 | Q27: 半期
Q28: 年度
G29: ★ BDM 故障 | Q29: 半期
Q30: 年度
G31: 計 | K31: (b) | Q31: 半期
Q32: 年度
D33: ★ 予 知 修 理 | K33: (c) | Q33: 半期
Q34: 年度
G35: 計 (a)+(b)+(c) | K35: (d) | Q35: 半期
Q36: 年度
C37: 作業計画性分類 | D37: 計 画 作 業 件 数 | G37: 予防保全作業件数 | K37: (e) | Q37: 半期
Q38: 年度
G39: その他計画作業件数 | Q39: 半期
Q40: 年度
G41: 小計 | K41: (f) | Q41: 半期
Q42: 年度
D43: 計 画 外 作 業 件 数 | G43: 突発作業件数 | K43: (g) | Q43: 半期
...

Sheet 期報
B2: MQ指標実績表（期報） | J2: =TEXT(年報!BY2,"yyyy年度下期") -> @対象年月
AO5: 工場 | AP5: =月報!S5 -> @工場
AO6: プラント | AP6: =月報!S6 -> @プラント
AO7: 工程 | AP7: =月報!S7 -> @工程
AO8: 職種 | AP8: =月報!S8 -> @職種
K10: =年報!AO10 -> #VALUE! | P10: =年報!AT10 -> #VALUE! | U10: =年報!AY10 -> #VALUE! | Z10: =年報!BD10 -> #VALUE! | AE10: =年報!BI10 -> #VALUE! | AJ10: =年報!BN10 -> #VALUE! | AO10: 期累計
F11: 項 目 | K11: 機 械 | L11: 電 気 | M11: 計 装 | N11: その他 | O11: 合 計 | P11: 機 械 | Q11: 電 気 | R11: 計 装 | S11: その他 | T11: 合 計 | U11: 機 械 | V11: 電 気 | W11: 計 装 | X11: その他 | Y11: 合 計 | Z11: 機 械 | AA11: 電 気 | AB11: 計 装 | AC11: その他 | AD11: 合 計 | AE11: 機 械 | AF11: 電 気 | AG11: 計 装 | AH11: その他 | AI11: 合 計 | AJ11: 機 械 | AK11: 電 気 | AL11: 計 装 | AM11: その他 | AN11: 合 計 | AO11: 機 械 | AP11: 電 気 | AQ11: 計 装 | AR11: その他 | AS11: 合 計
B12: 系 の 停 止 | C12: ★ 系 停 止 回 数 | F12: ★ 保全要因 | K12: =年報!AO12 -> @集計項目出力31 | L12: =年報!AP12 -> @集計項目出力32 | M12: =年報!AQ12 -> @集計項目出力33 | N12: =年報!AR12 -> @集計項目出力34 | O12: =年報!AS12 -> @集計項目出力35 | P12: =年報!AT12 -> @集計項目出力36 | Q12: =年報!AU12 -> @集計項目出力37 | R12: =年報!AV12 -> @集計項目出力38 | ... AN12: =年報!BR12 -> @集計項目出力60 | AO12: =月報!R13 -> @集計項目出力6 | AP12: =月報!S13 -> @集計項目出力7 | AQ12: =月報!T13 -> @集計項目出力8 | AR12: =月報!U13 -> @集計項目出力9 | AS12: =月報!V13 -> @集計項目出力10
F14: ★ 製造要因 | K14: =年報!AO14 -> 0 | L14: =年報!AP14 -> 0 | M14: =年報!AQ14 -> 0 | N14: =年報!AR14 -> 0 | O14: =年報!AS14 -> 0 | P14: =年報!AT14 -> 0 | Q14: =年報!AU14 -> 0 | R14: =年報!AV14 -> 0 | ... AN14: =年報!BR14 -> 0 | AO14: =月報!R15 -> 0 | AP14: =月報!S15 -> 0 | AQ14: =月報!T15 -> 0 | AR14: =月報!U15 -> 0 | AS14: =月報!V15 -> 0
F16: 計 | K16: =年報!AO16 -> 0 | L16: =年報!AP16 -> 0 | M16: =年報!AQ16 -> 0 | N16: =年報!AR16 -> 0 | O16: =年報!AS16 -> 0 | P16: =年報!AT16 -> 0 | Q16: =年報!AU16 -> 0 | R16: =年報!AV16 -> 0 | ... AN16: =年報!BR16 -> 0 | AO16: =月報!R17 -> 0 | AP16: =月報!S17 -> 0 | AQ16: =月報!T17 -> 0 | AR16: =月報!U17 -> 0 | AS16: =月報!V17 -> 0
C18: ★ 系 停 止 時 間 （保全要因） ［Ｈｒ] | K18: =年報!AO18 -> 0 | L18: =年報!AP18 -> 0 | M18: =年報!AQ18 -> 0 | N18: =年報!AR18 -> 0 | O18: =年報!AS18 -> 0 | P18: =年報!AT18 -> 0 | Q18: =年報!AU18 -> 0 | R18: =年報!AV18 -> 0 | ... AN18: =年報!BR18 -> 0 | AO18: =月報!R19 -> 0 | AP18: =月報!S19 -> 0 | AQ18: =月報!T19 -> 0 | AR18: =月報!U19 -> 0 | AS18: =月報!V19 -> 0
B20: 故障修理件数 | C20: ★ 故 障 1 | F20: ★ TBM 故障 | K20: =年報!AO20 -> 0 | L20: =年報!AP20 -> 0 | M20: =年報!AQ20 -> 0 | N20: =年報!AR20 -> 0 | O20: =年報!AS20 -> 0 | P20: =年報!AT20 -> 0 | Q20: =年報!AU20 -> 0 | R20: =年報!AV20 -> 0 | ... AN20: =年報!BR20 -> 0 | AO20: =月報!R21 -> 0 | AP20: =月報!S21 -> 0 | AQ20: =月報!T21 -> 0 | AR20: =月報!U21 -> 0 | AS20: =月報!V21 -> 0
F22: ★ CBM 想定外故障 | K22: =年報!AO22 -> 0 | L22: =年報!AP22 -> 0 | M22: =年報!AQ22 -> 0 | N22: =年報!AR22 -> 0 | O22: =年報!AS22 -> 0 | P22: =年報!AT22 -> 0 | Q22: =年報!AU22 -> 0 | R22: =年報!AV22 -> 0 | ... AN22: =年報!BR22 -> 0 | AO22: =月報!R23 -> 0 | AP22: =月報!S23 -> 0 | AQ22: =月報!T23 -> 0 | AR22: =月報!U23 -> 0 | AS22: =月報!V23 -> 0
F24: 計 | J24: (a) | K24: =年報!AO24 -> 0 | L24: =年報!AP24 -> 0 | M24: =年報!AQ24 -> 0 | N24: =年報!AR24 -> 0 | O24: =年報!AS24 -> 0 | P24: =年報!AT24 -> 0 | Q24: =年報!AU24 -> 0 | R24: =年報!AV24 -> 0 | ... AN24: =年報!BR24 -> 0 | AO24: =月報!R25 -> 0 | AP24: =月報!S25 -> 0 | AQ24: =月報!T25 -> 0 | AR24: =月報!U25 -> 0 | AS24: =月報!V25 -> 0
C26: ★ 故 障 2 | F26: ★ CBM 想定内故障 | K26: =年報!AO26 -> 0 | L26: =年報!AP26 -> 0 | M26: =年報!AQ26 -> 0 | N26: =年報!AR26 -> 0 | O26: =年報!AS26 -> 0 | P26: =年報!AT26 -> 0 | Q26: =年報!AU26 -> 0 | R26: =年報!AV26 -> 0 | ... AN26: =年報!BR26 -> 0 | AO26: =月報!R27 -> 0 | AP26: =月報!S27 -> 0 | AQ26: =月報!T27 -> 0 | AR26: =月報!U27 -> 0 | AS26: =月報!V27 -> 0
F28: ★ BDM 故障 | K28: =年報!AO28 -> 0 | L28: =年報!AP28 -> 0 | M28: =年報!AQ28 -> 0 | N28: =年報!AR28 -> 0 | O28: =年報!AS28 -> 0 | P28: =年報!AT28 -> 0 | Q28: =年報!AU28 -> 0 | R28: =年報!AV28 -> 0 | ... AN28: =年報!BR28 -> 0 | AO28: =月報!R29 -> 0 | AP28: =月報!S29 -> 0 | AQ28: =月報!T29 -> 0 | AR28: =月報!U29 -> 0 | AS28: =月報!V29 -> 0
F30: 計 | J30: (b) | K30: =年報!AO30 -> 0 | L30: =年報!AP30 -> 0 | M30: =年報!AQ30 -> 0 | N30: =年報!AR30 -> 0 | O30: =年報!AS30 -> 0 | P30: =年報!AT30 -> 0 | Q30: =年報!AU30 -> 0 | R30: =年報!AV30 -> 0 | ... AN30: =年報!BR30 -> 0 | AO30: =月報!R31 -> 0 | AP30: =月報!S31 -> 0 | AQ30: =月報!T31 -> 0 | AR30: =月報!U31 -> 0 | AS30: =月報!V31 -> 0
C32: ★ 予 知 修 理 | J32: (c) | K32: =年報!AO32 -> 0 | L32: =年報!AP32 -> 0 | M32: =年報!AQ32 -> 0 | N32: =年報!AR32 -> 0 | O32: =年報!AS32 -> 0 | P32: =年報!AT32 -> 0 | Q32: =年報!AU32 -> 0 | R32: =年報!AV32 -> 0 | ... AN32: =年報!BR32 -> 0 | AO32: =月報!R33 -> 0 | AP32: =月報!S33 -> 0 | AQ32: =月報!T33 -> 0 | AR32: =月報!U33 -> 0 | AS32: =月報!V33 -> 0
F34: 計 (a)+(b)+(c) | J34: (d) | K34: =年報!AO34 -> 0 | L34: =年報!AP34 -> 0 | M34: =年報!AQ34 -> 0 | N34: =年報!AR34 -> 0 | O34: =年報!AS34 -> 0 | P34: =年報!AT34 -> 0 | Q34: =年報!AU34 -> 0 | R34: =年報!AV34 -> 0 | ... AN34: =年報!BR34 -> 0 | AO34: =月報!R35 -> 0 | AP34: =月報!S35 -> 0 | AQ34: =月報!T35 -> 0 | AR34: =月報!U35 -> 0 | AS34: =月報!V35 -> 0
B36: 作業計画性分類 | C36: 計 画 作 業 件 数 | F36: 予防保全作業件数 | J36: (e) | K36: =年報!AO36 -> 0 | L36: =年報!AP36 -> 0 | M36: =年報!AQ36 -> 0 | N36: =年報!AR36 -> 0 | O36: =年報!AS36 -> 0 | P36: =年報!AT36 -> 0 | Q36: =年報!AU36 -> 0 | R36: =年報!AV36 -> 0 | ... AN36: =年報!BR36 -> 0 | AO36: =月報!R37 -> 0 | AP36: =月報!S37 -> 0 | AQ36: =月報!T37 -> 0 | AR36: =月報!U37 -> 0 | AS36: =月報!V37 -> 0
F38: その他計画作業件数 | K38: =年報!AO38 -> 0 | L38: =年報!AP38 -> 0 | M38: =年報!AQ38 -> 0 | N38: =年報!AR38 -> 0 | O38: =年報!AS38 -> 0 | P38: =年報!AT38 -> 0 | Q38: =年報!AU38 -> 0 | R38: =年報!AV38 -> 0 | ... AN38: =年報!BR38 -> 0 | AO38: =月報!R39 -> 0 | AP38: =月報!S39 -> 0 | AQ38: =月報!T39 -> 0 | AR38: =月報!U39 -> 0 | AS38: =月報!V39 -> 0
F40: 小計 | J40: (f) | K40: =年報!AO40 -> 0 | L40: =年報!AP40 -> 0 | M40: =年報!AQ40 -> 0 | N40: =年報!AR40 -> 0 | O40: =年報!AS40 -> 0 | P40: =年報!AT40 -> 0 | Q40: =年報!AU40 -> 0 | R40: =年報!AV40 -> 0 | ... AN40: =年報!BR40 -> 0 | AO40: =月報!R41 -> 0 | AP40: =月報!S41 -> 0 | AQ40: =月報!T41 -> 0 | AR40: =月報!U41 -> 0 | AS40: =月報!V41 -> 0
C42: 計 画 外 作 業 件 数 | F42: 突発作業件数 | J42: (g) | K42: =年報!AO42 -> 0 | L42: =年報!AP42 -> 0 | M42: =年報!AQ42 -> 0 | N42: =年報!AR42 -> 0 | O42: =年報!AS42 -> 0 | P42: =年報!AT42 -> 0 | Q42: =年報!AU42 -> 0 | R42: =年報!AV42 -> 0 | ... AN42: =年報!BR42 -> 0 | AO42: =月報!R43 -> 0 | AP42: =月報!S43 -> 0 | AQ42: =月報!T43 -> 0 | AR42: =月報!U43 -> 0 | AS42: =月報!V43 -> 0
F44: その他計画外作業件数 | K44: =年報!AO44 -> 0 | L44: =年報!AP44 -> 0 | M44: =年報!AQ44 -> 0 | N44: =年報!AR44 -> 0 | O44: =年報!AS44 -> 0 | P44: =年報!AT44 -> 0 | Q44: =年報!AU44 -> 0 | R44: =年報!AV44 -> 0 | ... AN44: =年報!BR44 -> 0 | AO44: =月報!R45 -> 0 | AP44: =月報!S45 -> 0 | AQ44: =月報!T45 -> 0 | AR44: =月報!U45 -> 0 | AS44: =月報!V45 -> 0
F46: 小計 | J46: (h) | K46: =年報!AO46 -> 0 | L46: =年報!AP46 -> 0 | M46: =年報!AQ46 -> 0 | N46: =年報!AR46 -> 0 | O46: =年報!AS46 -> 0 | P46: =年報!AT46 -> 0 | Q46: =年報!AU46 -> 0 | R46: =年報!AV46 -> 0 | ... AN46: =年報!BR46 -> 0 | AO46: =月報!R47 -> 0 | AP46: =月報!S47 -> 0 | AQ46: =月報!T47 -> 0 | AR46: =月報!U47 -> 0 | AS46: =月報!V47 -> 0
C48: ★ 作 業 総 件 数 | F48: 計 (f)+(h) | J48: (i) | K48: =年報!AO48 -> 0 | L48: =年報!AP48 -> 0 | M48: =年報!AQ48 -> 0 | N48: =年報!AR48 -> 0 | O48: =年報!AS48 -> 0 | P48: =年報!AT48 -> 0 | Q48: =年報!AU48 -> 0 | R48: =年報!AV48 -> 0 | ... AN48: =年報!BR48 -> 0 | AO48: =月報!R49 -> 0 | AP48: =月報!S49 -> 0 | AQ48: =月報!T49 -> 0 | AR48: =月報!U49 -> 0 | AS48: =月報!V49 -> 0
C50: ★ 計 画 作 業 率 | F50: ［=(f)/(i)*100］ | K50: =年報!AO50 -> 0 | L50: =年報!AP50 -> 0 | M50: =年報!AQ50 -> 0 | N50: =年報!AR50 -> 0 | O50: =年報!AS50 -> 0 | P50: =年報!AT50 -> 0 | Q50: =年報!AU50 -> 0 | R50: =年報!AV50 -> 0 | ... AN50: =年報!BR50 -> 0 | AO50: =月報!R51 -> 0 | AP50: =月報!S51 -> 0 | AQ50: =月報!T51 -> 0 | AR50: =月報!U51 -> 0 | AS50: =月報!V51 -> 0
C52: 予 防 保 全 作 業 率 | F52: ［=(e’)/(i)*100] | K52: =年報!AO52 -> 0 | L52: =年報!AP52 -> 0 | M52: =年報!AQ52 -> 0 | N52: =年報!AR52 -> 0 | O52: =年報!AS52 -> 0 | P52: =年報!AT52 -> 0 | Q52: =年報!AU52 -> 0 | R52: =年報!AV52 -> 0 | ... AN52: =年報!BR52 -> 0 | AO52: =月報!R53 -> 0 | AP52: =月報!S53 -> 0 | AQ52: =月報!T53 -> 0 | AR52: =月報!U53 -> 0 | AS52: =月報!V53 -> 0
C54: 突 発 作 業 率 | F54: ［=(g)/(i)*100］ | K54: =年報!AO54 -> 0 | L54: =年報!AP54 -> 0 | M54: =年報!AQ54 -> 0 | N54: =年報!AR54 -> 0 | O54: =年報!AS54 -> 0 | P54: =年報!AT54 -> 0 | Q54: =年報!AU54 -> 0 | R54: =年報!AV54 -> 0 | ... AN54: =年報!BR54 -> 0 | AO54: =月報!R55 -> 0 | AP54: =月報!S55 -> 0 | AQ54: =月報!T55 -> 0 | AR54: =月報!U55 -> 0 | AS54: =月報!V55 -> 0
B56: 作業性格分類 | C56: 予 防 保 全 | E56: 予 防 保 全 作 業 件 数 （法定検査、予防検査、定期整備、計画修理、計画塗装） | J56: (e’) | K56: =年報!AO56 -> 0 | L56: =年報!AP56 -> 0 | M56: =年報!AQ56 -> 0 | N56: =年報!AR56 -> 0 | O56: =年報!AS56 -> 0 | P56: =年報!AT56 -> 0 | Q56: =年報!AU56 -> 0 | R56: =年報!AV56 -> 0 | ... AN56: =年報!BR56 -> 0 | AO56: =月報!R57 -> 0 | AP56: =月報!S57 -> 0 | AQ56: =月報!T57 -> 0 | AR56: =月報!U57 -> 0 | AS56: =月報!V57 -> 0
C58: 事 後 保 全 | E58: 故 障 修 理 件 数 (故障1+故障2+予知修理） | J58: (d) | K58: =年報!AO58 -> 0 | L58: =年報!AP58 -> 0 | M58: =年報!AQ58 -> 0 | N58: =年報!AR58 -> 0 | O58: =年報!AS58 -> 0 | P58: =年報!AT58 -> 0 | Q58: =年報!AU58 -> 0 | R58: =年報!AV58 -> 0 | ... AN58: =年報!BR58 -> 0 | AO58: =月報!R59 -> 0 | AP58: =月報!S59 -> 0 | AQ58: =月報!T59 -> 0 | AR58: =月報!U59 -> 0 | AS58: =月報!V59 -> 0
E60: そ の 他 作 業 件 数 （簡易保全、トラブル調査、その他） | K60: =年報!AO60 -> 0 | L60: =年報!AP60 -> 0 | M60: =年報!AQ60 -> 0 | N60: =年報!AR60 -> 0 | O60: =年報!AS60 -> 0 | P60: =年報!AT60 -> 0 | Q60: =年報!AU60 -> 0 | R60: =年報!AV60 -> 0 | ... AN60: =年報!BR60 -> 0 | AO60: =月報!R61 -> 0 | AP60: =月報!S61 -> 0 | AQ60: =月報!T61 -> 0 | AR60: =月報!U61 -> 0 | AS60: =月報!V61 -> 0
C62: 製 造 関 連 | E62: 製 造 関 連 作 業 件 数 （生産計画変更、クリーニング、製造件名修繕、改善） | K62: =年報!AO62 -> 0 | L62: =年報!AP62 -> 0 | M62: =年報!AQ62 -> 0 | N62: =年報!AR62 -> 0 | O62: =年報!AS62 -> 0 | P62: =年報!AT62 -> 0 | Q62: =年報!AU62 -> 0 | R62: =年報!AV62 -> 0 | ... AN62: =年報!BR62 -> 0 | AO62: =月報!R63 -> 0 | AP62: =月報!S63 -> 0 | AQ62: =月報!T63 -> 0 | AR62: =月報!U63 -> 0 | AS62: =月報!V63 -> 0
C64: ★ 作 業 総 件 数 | J64: (j) | K64: =年報!AO64 -> 0 | L64: =年報!AP64 -> 0 | M64: =年報!AQ64 -> 0 | N64: =年報!AR64 -> 0 | O64: =年報!AS64 -> 0 | P64: =年報!AT64 -> 0 | Q64: =年報!AU64 -> 0 | R64: =年報!AV64 -> 0 | ... AN64: =年報!BR64 -> 0 | AO64: =月報!R65 -> 0 | AP64: =月報!S65 -> 0 | AQ64: =月報!T65 -> 0 | AR64: =月報!U65 -> 0 | AS64: =月報!V65 -> 0
B66: その他 | C66: ★ 呼 び 出 し 回 数 | K66: =年報!AO66 -> 0 | L66: =年報!AP66 -> 0 | M66: =年報!AQ66 -> 0 | N66: =年報!AR66 -> 0 | O66: =年報!AS66 -> 0 | P66: =年報!AT66 -> 0 | Q66: =年報!AU66 -> 0 | R66: =年報!AV66 -> 0 | ... AN66: =年報!BR66 -> 0 | AO66: =月報!R67 -> 0 | AP66: =月報!S67 -> 0 | AQ66: =月報!T67 -> 0 | AR66: =月報!U67 -> 0 | AS66: =月報!V67 -> 0

Sheet 年報
B2: MQ指標実績表（年報） | J2: =TEXT(BY2,"yyyy年度") -> @対象年月 | BY2: @対象年月
BY3: @年度開始月
BS4: 工場 | BT4: =月報!S5 -> @工場
BS5: プラント | BT5: =月報!S6 -> @プラント
BS6: 工程 | BT6: =月報!S7 -> @工程
BS7: 職種 | BT7: =月報!S8 -> @職種
K10: =TEXT(BY3,"0月") -> @年度開始月 | P10: =TEXT(IF($BY3+1>12,$BY3+1-12,$BY3+1),"0月") -> #VALUE! | U10: =TEXT(IF($BY3+2>12,$BY3+2-12,$BY3+2),"0月") -> #VALUE! | Z10: =TEXT(IF($BY3+3>12,$BY3+3-12,$BY3+3),"0月") -> #VALUE! | AE10: =TEXT(IF($BY3+4>12,$BY3+4-12,$BY3+4),"0月") -> #VALUE! | AJ10: =TEXT(IF($BY3+5>12,$BY3+5-12,$BY3+5),"0月") -> #VALUE! | AO10: =TEXT(IF($BY3+6>12,$BY3+6-12,$BY3+6),"0月") -> #VALUE! | AT10: =TEXT(IF($BY3+7>12,$BY3+7-12,$BY3+7),"0月") -> #VALUE! | AY10: =TEXT(IF($BY3+8>12,$BY3+8-12,$BY3+8),"0月") -> #VALUE! | BD10: =TEXT(IF($BY3+9>12,$BY3+9-12,$BY3+9),"0月") -> #VALUE! | BI10: =TEXT(IF($BY3+10>12,$BY3+10-12,$BY3+10),"0月") -> #VALUE! | BN10: =TEXT(IF($BY3+11>12,$BY3+11-12,$BY3+11),"0月") -> #VALUE! | BS10: 年度累計
F11: 項 目 | K11: 機 械 | L11: 電 気 | M11: 計 装 | N11: その他 | O11: 合 計 | P11: 機 械 | Q11: 電 気 | R11: 計 装 | S11: その他 | T11: 合 計 | U11: 機 械 | V11: 電 気 | W11: 計 装 | X11: その他 | Y11: 合 計 | Z11: 機 械 | AA11: 電 気 | AB11: 計 装 | AC11: その他 | AD11: 合 計 | AE11: 機 械 | AF11: 電 気 | AG11: 計 装 | AH11: その他 | AI11: 合 計 | AJ11: 機 械 | AK11: 電 気 | AL11: 計 装 | AM11: その他 | AN11: 合 計 | AO11: 機 械 | AP11: 電 気 | AQ11: 計 装 | AR11: その他 | AS11: 合 計 | AT11: 機 械 | AU11: 電 気 | AV11: 計 装 | AW11: その他 | AX11: 合 計 | AY11: 機 械 | AZ11: 電 気 | BA11: 計 装 | BB11: その他 | BC11: 合 計 | BD11: 機 械 | BE11: 電 気 | BF11: 計 装 | BG11: その他 | BH11: 合 計 | BI11: 機 械 | BJ11: 電 気 | BK11: 計 装 | BL11: その他 | BM11: 合 計 | BN11: 機 械 | BO11: 電 気 | BP11: 計 装 | BQ11: その他 | BR11: 合 計 | BS11: 機 械 | BT11: 電 気 | BU11: 計 装 | BV11: その他 | BW11: 合 計
B12: 系 の 停 止 | C12: ★ 系 停 止 回 数 | F12: ★ 保全要因 | K12: @集計項目出力1 | L12: @集計項目出力2 | M12: @集計項目出力3 | N12: @集計項目出力4 | O12: @集計項目出力5 | P12: @集計項目出力6 | Q12: @集計項目出力7 | R12: @集計項目出力8 | S12: @集計項目出力9 | T12: @集計項目出力10 | U12: @集計項目出力11 | V12: @集計項目出力12 | W12: @集計項目出力13 | X12: @集計項目出力14 | Y12: @集計項目出力15 | Z12: @集計項目出力16 | AA12: @集計項目出力17 | AB12: @集計項目出力18 | AC12: @集計項目出力19 | AD12: @集計項目出力20 | AE12: @集計項目出力21 | AF12: @集計項目出力22 | AG12: @集計項目出力23 | AH12: @集計項目出力24 | AI12: @集計項目出力25 | AJ12: @集計項目出力26 | AK12: @集計項目出力27 | AL12: @集計項目出力28 | AM12: @集計項目出力29 | AN12: @集計項目出力30 | AO12: @集計項目出力31 | AP12: @集計項目出力32 | AQ12: @集計項目出力33 | AR12: @集計項目出力34 | AS12: @集計項目出力35 | AT12: @集計項目出力36 | AU12: @集計項目出力37 | AV12: @集計項目出力38 | AW12: @集計項目出力39 | AX12: @集計項目出力40 | AY12: @集計項目出力41 | AZ12: @集計項目出力42 | BA12: @集計項目出力43 | BB12: @集計項目出力44 | BC12: @集計項目出力45 | BD12: @集計項目出力46 | BE12: @集計項目出力47 | BF12: @集計項目出力48 | BG12: @集計項目出力49 | BH12: @集計項目出力50 | BI12: @集計項目出力51 | BJ12: @集計項目出力52 | BK12: @集計項目出力53 | BL12: @集計項目出力54 | BM12: @集計項目出力55 | BN12: @集計項目出力56 | BO12: @集計項目出力57 | BP12: @集計項目出力58 | BQ12: @集計項目出力59 | BR12: @集計項目出力60 | BS12: =月報!R14 -> @集計項目出力11 | BT12: =月報!S14 -> @集計項目出力12 | BU12: =月報!T14 -> @集計項目出力13 | BV12: =月報!U14 -> @集計項目出力14 | BW12: =月報!V14 -> @集計項目出力15
F14: ★ 製造要因 | BS14: =月報!R16 -> 0 | BT14: =月報!S16 -> 0 | BU14: =月報!T16 -> 0 | BV14: =月報!U16 -> 0 | BW14: =月報!V16 -> 0
F16: 計 | BS16: =月報!R18 -> 0 | BT16: =月報!S18 -> 0 | BU16: =月報!T18 -> 0 | BV16: =月報!U18 -> 0 | BW16: =月報!V18 -> 0
C18: ★ 系 停 止 時 間 （保全要因） ［Ｈｒ] | BS18: =月報!R20 -> 0 | BT18: =月報!S20 -> 0 | BU18: =月報!T20 -> 0 | BV18: =月報!U20 -> 0 | BW18: =月報!V20 -> 0
B20: 故障修理件数 | C20: ★ 故 障 1 | F20: ★ TBM 故障 | BS20: =月報!R22 -> 0 | BT20: =月報!S22 -> 0 | BU20: =月報!T22 -> 0 | BV20: =月報!U22 -> 0 | BW20: =月報!V22 -> 0
F22: ★ CBM 想定外故障 | BS22: =月報!R24 -> 0 | BT22: =月報!S24 -> 0 | BU22: =月報!T24 -> 0 | BV22: =月報!U24 -> 0 | BW22: =月報!V24 -> 0
F24: 計 | J24: (a) | BS24: =月報!R26 -> 0 | BT24: =月報!S26 -> 0 | BU24: =月報!T26 -> 0 | BV24: =月報!U26 -> 0 | BW24: =月報!V26 -> 0
C26: ★ 故 障 2 | F26: ★ CBM 想定内故障 | BS26: =月報!R28 -> 0 | BT26: =月報!S28 -> 0 | BU26: =月報!T28 -> 0 | BV26: =月報!U28 -> 0 | BW26: =月報!V28 -> 0
F28: ★ BDM 故障 | BS28: =月報!R30 -> 0 | BT28: =月報!S30 -> 0 | BU28: =月報!T30 -> 0 | BV28: =月報!U30 -> 0 | BW28: =月報!V30 -> 0
F30: 計 | J30: (b) | BS30: =月報!R32 -> 0 | BT30: =月報!S32 -> 0 | BU30: =月報!T32 -> 0 | BV30: =月報!U32 -> 0 | BW30: =月報!V32 -> 0
C32: ★ 予 知 修 理 | J32: (c) | BS32: =月報!R34 -> 0 | BT32: =月報!S34 -> 0 | BU32: =月報!T34 -> 0 | BV32: =月報!U34 -> 0 | BW32: =月報!V34 -> 0
F34: 計 (a)+(b)+(c) | J34: (d) | BS34: =月報!R36 -> 0 | BT34: =月報!S36 -> 0 | BU34: =月報!T36 -> 0 | BV34: =月報!U36 -> 0 | BW34: =月報!V36 -> 0
B36: 作業計画性分類 | C36: 計 画 作 業 件 数 | F36: 予防保全作業件数 | J36: (e) | BS36: =月報!R38 -> 0 | BT36: =月報!S38 -> 0 | BU36: =月報!T38 -> 0 | BV36: =月報!U38 -> 0 | BW36: =月報!V38 -> 0
F38: その他計画作業件数 | BS38: =月報!R40 -> 0 | BT38: =月報!S40 -> 0 | BU38: =月報!T40 -> 0 | BV38: =月報!U40 -> 0 | BW38: =月報!V40 -> 0
F40: 小計 | J40: (f) | BS40: =月報!R42 -> 0 | BT40: =月報!S42 -> 0 | BU40: =月報!T42 -> 0 | BV40: =月報!U42 -> 0 | BW40: =月報!V42 -> 0
C42: 計 画 外 作 業 件 数 | F42: 突発作業件数 | J42: (g) | BS42: =月報!R44 -> 0 | BT42: =月報!S44 -> 0 | BU42: =月報!T44 -> 0 | BV42: =月報!U44 -> 0 | BW42: =月報!V44 -> 0
F44: その他計画外作業件数 | BS44: =月報!R46 -> 0 | BT44: =月報!S46 -> 0 | BU44: =月報!T46 -> 0 | BV44: =月報!U46 -> 0 | BW44: =月報!V46 -> 0
F46: 小計 | J46: (h) | BS46: =月報!R48 -> 0 | BT46: =月報!S48 -> 0 | BU46: =月報!T48 -> 0 | BV46: =月報!U48 -> 0 | BW46: =月報!V48 -> 0
C48: ★ 作 業 総 件 数 | F48: 計 (f)+(h) | J48: (i) | BS48: =月報!R50 -> 0 | BT48: =月報!S50 -> 0 | BU48: =月報!T50 -> 0 | BV48: =月報!U50 -> 0 | BW48: =月報!V50 -> 0
C50: ★ 計 画 作 業 率 | F50: ［=(f)/(i)*100］ | BS50: =月報!R52 -> 0 | BT50: =月報!S52 -> 0 | BU50: =月報!T52 -> 0 | BV50: =月報!U52 -> 0 | BW50: =月報!V52 -> 0
C52: 予 防 保 全 作 業 率 | F52: ［=(e’)/(i)*100] | BS52: =月報!R54 -> 0 | BT52: =月報!S54 -> 0 | BU52: =月報!T54 -> 0 | BV52: =月報!U54 -> 0 | BW52: =月報!V54 -> 0
C54: 突 発 作 業 率 | F54: ［=(g)/(i)*100］ | BS54: =月報!R56 -> 0 | BT54: =月報!S56 -> 0 | BU54: =月報!T56 -> 0 | BV54: =月報!U56 -> 0 | BW54: =月報!V56 -> 0
B56: 作業性格分類 | C56: 予 防 保 全 | E56: 予 防 保 全 作 業 件 数 （法定検査、予防検査、定期整備、計画修理、計画塗装） | J56: (e’) | BS56: =月報!R58 -> 0 | BT56: =月報!S58 -> 0 | BU56: =月報!T58 -> 0 | BV56: =月報!U58 -> 0 | BW56: =月報!V58 -> 0
C58: 事 後 保 全 | E58: 故 障 修 理 件 数 (故障1+故障2+予知修理） | J58: (d) | BS58: =月報!R60 -> 0 | BT58: =月報!S60 -> 0 | BU58: =月報!T60 -> 0 | BV58: =月報!U60 -> 0 | BW58: =月報!V60 -> 0
E60: そ の 他 作 業 件 数 （簡易保全、トラブル調査、その他） | BS60: =月報!R62 -> 0 | BT60: =月報!S62 -> 0 | BU60: =月報!T62 -> 0 | BV60: =月報!U62 -> 0 | BW60: =月報!V62 -> 0
C62: 製 造 関 連 | E62: 製 造 関 連 作 業 件 数 （生産計画変更、クリーニング、製造件名修繕、改善） | BS62: =月報!R64 -> 0 | BT62: =月報!S64 -> 0 | BU62: =月報!T64 -> 0 | BV62: =月報!U64 -> 0 | BW62: =月報!V64 -> 0
C64: ★ 作 業 総 件 数 | J64: (j) | BS64: =月報!R66 -> 0 | BT64: =月報!S66 -> 0 | BU64: =月報!T66 -> 0 | BV64: =月報!U66 -> 0 | BW64: =月報!V66 -> 0
B66: その他 | C66: ★ 呼 び 出 し 回 数 | BS66: =月報!R68 -> 0 | BT66: =月報!S68 -> 0 | BU66: =月報!T68 -> 0 | BV66: =月報!U68 -> 0 | BW66: =月報!V68 -> 0
